/home/ancuser/anaconda3/lib/python3.6/site-packages/pandas/core/generic.py:1345: UserWarning: The spaces in these column names will not be changed. In pandas versions < 0.14, spaces were converted to underscores.
  chunksize=chunksize, dtype=dtype)
Traceback (most recent call last):
  File "pandas/_libs/parsers.pyx", line 1162, in pandas._libs.parsers.TextReader._convert_tokens (pandas/_libs/parsers.c:14858)
  File "pandas/_libs/parsers.pyx", line 1273, in pandas._libs.parsers.TextReader._convert_with_dtype (pandas/_libs/parsers.c:17119)
  File "pandas/_libs/parsers.pyx", line 1289, in pandas._libs.parsers.TextReader._string_convert (pandas/_libs/parsers.c:17347)
  File "pandas/_libs/parsers.pyx", line 1524, in pandas._libs.parsers._string_box_utf8 (pandas/_libs/parsers.c:23041)
UnicodeDecodeError: 'utf-8' codec can't decode byte 0x93 in position 13: invalid start byte

During handling of the above exception, another exception occurred:

Traceback (most recent call last):
  File "analyze_medicare_data.py", line 88, in create_tables
  File "/home/ancuser/anaconda3/lib/python3.6/site-packages/pandas/io/parsers.py", line 655, in parser_f
    return _read(filepath_or_buffer, kwds)
  File "/home/ancuser/anaconda3/lib/python3.6/site-packages/pandas/io/parsers.py", line 411, in _read
    data = parser.read(nrows)
  File "/home/ancuser/anaconda3/lib/python3.6/site-packages/pandas/io/parsers.py", line 982, in read
    ret = self._engine.read(nrows)
  File "/home/ancuser/anaconda3/lib/python3.6/site-packages/pandas/io/parsers.py", line 1719, in read
    data = self._reader.read(nrows)
  File "pandas/_libs/parsers.pyx", line 890, in pandas._libs.parsers.TextReader.read (pandas/_libs/parsers.c:10862)
  File "pandas/_libs/parsers.pyx", line 912, in pandas._libs.parsers.TextReader._read_low_memory (pandas/_libs/parsers.c:11138)
  File "pandas/_libs/parsers.pyx", line 989, in pandas._libs.parsers.TextReader._read_rows (pandas/_libs/parsers.c:12175)
  File "pandas/_libs/parsers.pyx", line 1117, in pandas._libs.parsers.TextReader._convert_column_data (pandas/_libs/parsers.c:14136)
  File "pandas/_libs/parsers.pyx", line 1169, in pandas._libs.parsers.TextReader._convert_tokens (pandas/_libs/parsers.c:14972)
  File "pandas/_libs/parsers.pyx", line 1273, in pandas._libs.parsers.TextReader._convert_with_dtype (pandas/_libs/parsers.c:17119)
  File "pandas/_libs/parsers.pyx", line 1289, in pandas._libs.parsers.TextReader._string_convert (pandas/_libs/parsers.c:17347)
  File "pandas/_libs/parsers.pyx", line 1524, in pandas._libs.parsers._string_box_utf8 (pandas/_libs/parsers.c:23041)
UnicodeDecodeError: 'utf-8' codec can't decode byte 0x93 in position 13: invalid start byte

During handling of the above exception, another exception occurred:

Traceback (most recent call last):
  File "analyze_medicare_data.py", line 131, in <module>
  File "analyze_medicare_data.py", line 105, in create_tables
  File "/home/ancuser/anaconda3/lib/python3.6/site-packages/pandas/io/parsers.py", line 655, in parser_f
    return _read(filepath_or_buffer, kwds)
  File "/home/ancuser/anaconda3/lib/python3.6/site-packages/pandas/io/parsers.py", line 405, in _read
    parser = TextFileReader(filepath_or_buffer, **kwds)
  File "/home/ancuser/anaconda3/lib/python3.6/site-packages/pandas/io/parsers.py", line 762, in __init__
    self._make_engine(self.engine)
  File "/home/ancuser/anaconda3/lib/python3.6/site-packages/pandas/io/parsers.py", line 966, in _make_engine
    self._engine = CParserWrapper(self.f, **self.options)
  File "/home/ancuser/anaconda3/lib/python3.6/site-packages/pandas/io/parsers.py", line 1582, in __init__
    self._reader = parsers.TextReader(src, **kwds)
  File "pandas/_libs/parsers.pyx", line 394, in pandas._libs.parsers.TextReader.__cinit__ (pandas/_libs/parsers.c:4209)
  File "pandas/_libs/parsers.pyx", line 710, in pandas._libs.parsers.TextReader._setup_parser_source (pandas/_libs/parsers.c:8873)
FileNotFoundError: File b'/home/ancuser/auto_grader/sandbox/staging/HCAHPS - Hospital.csv.fix' does not exist
